Traceback (most recent call last):
  File "/home/charmm-gui/www/lib/ppm.py", line 10, in <module>
    response = requests.post(url, files=form_data, data=data)
  File "/home/charmm-gui/local/python-2.7.16/lib/python2.7/site-packages/requests/api.py", line 116, in post
    return request('post', url, data=data, json=json, **kwargs)
  File "/home/charmm-gui/local/python-2.7.16/lib/python2.7/site-packages/requests/api.py", line 60, in request
    return session.request(method=method, url=url, **kwargs)
  File "/home/charmm-gui/local/python-2.7.16/lib/python2.7/site-packages/requests/sessions.py", line 533, in request
    resp = self.send(prep, **send_kwargs)
  File "/home/charmm-gui/local/python-2.7.16/lib/python2.7/site-packages/requests/sessions.py", line 646, in send
    r = adapter.send(request, **kwargs)
  File "/home/charmm-gui/local/python-2.7.16/lib/python2.7/site-packages/requests/adapters.py", line 516, in send
    raise ConnectionError(e, request=request)
requests.exceptions.ConnectionError: HTTPConnectionPool(host='sunshine.phar.umich.edu', port=80): Max retries exceeded with url: /upload_file.php (Caused by NewConnectionError('<urllib3.connection.HTTPConnection object at 0x7fed6bc61350>: Failed to establish a new connection: [Errno 111] Connection refused',))
